<mujoco model="arm">
    <option timestep="0.01" jacobian="dense"/>
    <compiler inertiafromgeom="true" autolimits="true"/>

    <default>
        <joint armature="0.5" damping="0.1" limited="true" />
        <motor gear="50" ctrlrange="-1 1" />
    </default>

    <asset>
        <mesh file="arm/base_bottom.stl" />
        <mesh file="arm/base_top.stl" />
        <mesh file="arm/base_link.stl" />
        <mesh file="arm/camera.stl" />
        <mesh file="arm/ee_claw.stl" />
        <mesh file="arm/end_effector_base.stl" />
        <mesh file="arm/long_link.stl" />
        <mesh file="arm/medium_link.stl" />
        <mesh file="arm/short_link.stl" />
        <mesh file="arm/x_f.stl" />
        <mesh file="arm/x_m.stl" />
        <mesh file="arm/z_f.stl" />
        <mesh file="arm/z_m.stl" />

        <material name="steel" rgba="0.27 0.50 0.70 0.75" />
        <material name="aluminum" rgba="0.83 0.83 0.83 1" />
        <material name="abs" rgba="1 0 0.5 1" />
        <material name="floor" rgba="0.5 0.5 0.5 1" />
        <material name="debug" rgba="1 1 0.5 0.5" />
        <material name="camera" rgba="1 1 1 1" />
        <material name="target" rgba="0 1 0 1" />
    </asset>

    <worldbody>
        <geom name="floor" pos="0 0 0" size="5 5 0.01" type="plane" material="floor" />
        <light name="top" pos="0 0 2.5" dir="0 0 -1" diffuse="1 1 1" />
        <light name="front" pos="0 2.5 0" dir="0 -1 0" diffuse="1 1 1" />
        <light name="back" pos="0 -2.5 0" dir="0 1 0" diffuse="1 1 1" />
        <light name="left" pos="2.5 0 0" dir="-1 0 0" diffuse="1 1 1" />
        <light name="right" pos="-2.5 0 0" dir="1 0 0" diffuse="1 1 1" />

        <body name="base_bottom" pos="0 0 0.01">
            <geom name="base_bottom" type="mesh" mesh="base_bottom" material="steel" density="8000"/>
            <joint name="joint_1" pos="0 0 0.1" axis="0 0 1" type="hinge" limited="false"/>
            <body name="base_top" pos="0 0 0">
                <geom name="base_top" type="mesh" mesh="base_top" material="steel" density="8000"/>
                <body name="first_link" pos="0 0 0.3" euler="90 90 0">
                    <geom name="first_link" type="mesh" mesh="base_link" material="aluminum" density="2700"/>
                    <joint name="joint_2" pos="0 -.175 0" axis="1 0 0" type="hinge" limited="true" range="-90 90"/>
                    <body name="z_f_1" pos="0 0.235 0" euler="0 0 0">
                        <geom name="z_f_1" type="mesh" mesh="z_f" material="steel" density="8000"/>
                        <body name="z_m_1" pos="0 0.05 0" euler="180 180 0">
                            <geom name="z_m_1" type="mesh" mesh="z_m" material="steel" density="8000"/>
                            <joint name="joint_3" pos="0 .025 0" axis="-1 0 0" type="hinge" limited="true" range="-90 90"/>
                            <body name="second_link" pos="0 -0.235 0" euler="0 0 0">
                                <geom name="second_link" type="mesh" mesh="long_link" material="aluminum" density="2700"/>
                                <body name="z_f_2" pos="0 -0.235 0" euler="180 0 0">
                                    <geom name="z_f_2" type="mesh" mesh="z_f" material="steel" density="8000"/>
                                    <body name="z_m_2" pos="0 0.05 0" euler="180 180 0">
                                        <geom name="z_m_2" type="mesh" mesh="z_m" material="steel" density="8000"/>
                                        <joint name="joint_4" pos="0 .025 0" axis="1 0 0" type="hinge" limited="true" range="-90 90"/>
                                        <body name="third_link" pos="0 -0.11 0" euler="0 0 0">
                                            <geom name="third_link" type="mesh" mesh="medium_link" material="aluminum" density="2700"/>
                                            <body name="x_m_1" pos="0 -0.11 0" euler="180 0 0">
                                                <geom name="x_m_1" type="mesh" mesh="x_m" material="steel" density="8000"/>
                                                <body name="x_f_1" pos="0 0 0" euler="180 0 0">
                                                    <geom name="x_f_1" type="mesh" mesh="x_f" material="steel" density="8000"/>
                                                    <joint name="joint_5" pos="0 0 0" axis="0 -1 0" type="hinge" limited="false"/>
                                                    <body name="fourth_link" pos="0 -.11 0" euler="180 0 0">
                                                        <geom name="fourth_link" type="mesh" mesh="medium_link" material="aluminum" density="2700"/>
                                                        <body name="z_f_3" pos="0 .11 0" euler="0 0 0">
                                                            <geom name="z_f_3" type="mesh" mesh="z_f" material="steel" density="8000"/>
                                                            <body name="z_m_3" pos="0 0.05 0" euler="180 180 0">
                                                                <geom name="z_m_3" type="mesh" mesh="z_m" material="steel" density="8000"/>
                                                                <joint name="joint_6" pos="0 .025 0" axis="1 0 0" type="hinge" limited="true" range="-90 90"/>
                                                                <body name="fifth_link" pos="0 -0.05 0" euler="0 0 0">
                                                                    <geom name="fifth_link" type="mesh" mesh="short_link" material="aluminum" density="2700"/>
                                                                    <body name="x_m_2" pos="0 -0.05 0" euler="180 0 0">
                                                                        <geom name="x_m_2" type="mesh" mesh="x_m" material="steel" density="8000"/>
                                                                        <body name="end_effector_link" pos="0 0.12 -0.01" euler="0 0 0">
                                                                            <geom name="end_effector_link" type="mesh" mesh="end_effector_base" material="aluminum" density="2700"/>
                                                                            <joint name="joint_7" pos="0 0 0.01" axis="0 1 0" type="hinge" limited="false"/>
                                                                            <body name="ee_claw_1" pos="-0.035 -0.03 0.01" euler="0 0 45">
                                                                                <geom name="ee_claw_1" type="mesh" mesh="ee_claw" material="aluminum" density="2700"/>
                                                                                <!-- <joint name="joint_ee_1" pos="0 0 0" axis="0 0 1" type="hinge" limited="true" range="0 90"/> -->
                                                                            </body>
                                                                            <body name="ee_claw_2" pos="0.035 -0.03 0.01" euler="0 180 45">
                                                                                <geom name="ee_claw_2" type="mesh" mesh="ee_claw" material="aluminum"/>
                                                                                <!-- <joint name="joint_ee_2" pos="0 0 0" axis="0 0 1" type="hinge" limited="true" range="0 90"/> -->
                                                                            </body>
                                                                            <body name="camera" pos="0 0 0.01" euler="-90 0 0">
                                                                                <geom name="camera" type="mesh" mesh="camera" material="camera"/>
                                                                                <camera name="camera" mode="targetbody" target="end_effector_link" pos="0 0 0.1" euler="0 0 0"/>
                                                                            </body>
                                                                            <body name="target" pos="0 0.08 0.01">
                                                                                <geom name="target" type="sphere" size="0.01" material="target" density="0.1" contype="0" conaffinity="0"/>
                                                                                <site name="target" pos="0 0 0" size="0.01" rgba="1 0 0 1"/>
                                                                            </body>
                                                                        </body>
                                                                    </body>
                                                                </body>
                                                            </body>
                                                        </body>
                                                    </body>
                                                </body>
                                            </body>
                                        </body>
                                    </body>
                                </body>
                            </body>
                        </body>
                    </body>
                </body>
            </body>
        </body>
        
    </worldbody>
    <sensor>
        <framepos objtype="site" objname="target"/>
    </sensor>
    <actuator>
        <motor joint="joint_1" name="motor_1" forcerange="-1000 1000" gear="100" />
        <motor joint="joint_2" name="motor_2" forcerange="-1000 1000" gear="100" />
        <motor joint="joint_3" name="motor_3" forcerange="-1000 1000" gear="100" />
        <motor joint="joint_4" name="motor_4" forcerange="-1000 1000" gear="100" />
        <motor joint="joint_5" name="motor_5" forcerange="-1000 1000" gear="100" />
        <motor joint="joint_6" name="motor_6" forcerange="-1000 1000" gear="100" />
        <motor joint="joint_7" name="motor_7" forcerange="-1000 1000" gear="100" />
        <!-- <motor joint="joint_ee_1" name="motor_ee_1" />
        <motor joint="joint_ee_2" name="motor_ee_2" /> -->
    </actuator>
</mujoco>
